Learning rate set to 0.122239
0:	learn: 0.5509414	test: 0.5582800	best: 0.5582800 (0)	total: 549ms	remaining: 9m 8s
100:	learn: 0.6029260	test: 0.5912686	best: 0.5920404 (99)	total: 17.3s	remaining: 2m 34s
Stopped by overfitting detector  (100 iterations wait)

bestTest = 0.5920403756
bestIteration = 99

Shrink model to first 100 iterations.
Learning rate set to 0.122239
0:	learn: 0.5616212	test: 0.5571941	best: 0.5571941 (0)	total: 131ms	remaining: 2m 10s
100:	learn: 0.6034319	test: 0.5865585	best: 0.5893866 (50)	total: 17.2s	remaining: 2m 33s
200:	learn: 0.6217837	test: 0.5823517	best: 0.5905156 (110)	total: 30.1s	remaining: 1m 59s
Stopped by overfitting detector  (100 iterations wait)

bestTest = 0.5905155566
bestIteration = 110

Shrink model to first 111 iterations.
Learning rate set to 0.122239
0:	learn: 0.5844819	test: 0.5818453	best: 0.5818453 (0)	total: 157ms	remaining: 2m 36s
100:	learn: 0.6035594	test: 0.5984901	best: 0.5995519 (80)	total: 14.7s	remaining: 2m 10s
200:	learn: 0.6220844	test: 0.5958995	best: 0.6005902 (120)	total: 28.6s	remaining: 1m 53s
Stopped by overfitting detector  (100 iterations wait)

bestTest = 0.6005901972
bestIteration = 120

Shrink model to first 121 iterations.
Learning rate set to 0.122239
0:	learn: 0.5551986	test: 0.5581065	best: 0.5581065 (0)	total: 146ms	remaining: 2m 25s
17:02:25.183 | [38;5;160mERROR[0m   | Flow run[35m 'unique-orangutan'[0m - Crash detected! Execution was aborted by an interrupt signal.
--- Error logging to API ---
All connection attempts failed17:02:36.985 | [38;5;160mERROR[0m   | Flow run[35m 'unique-orangutan'[0m - Finished in state Running()
Traceback (most recent call last):
  File "C:\Users\maorb\Classes\Classical_ML\YDATA-kaggle-assignment\venv\Lib\site-packages\httpx\_transports\default.py", line 101, in map_httpcore_exceptions
    yield
  File "C:\Users\maorb\Classes\Classical_ML\YDATA-kaggle-assignment\venv\Lib\site-packages\httpx\_transports\default.py", line 250, in handle_request
    resp = self._pool.handle_request(req)
           ^^^^^^^^^^^^^^^^^^^^^^^^^^^^^^
  File "C:\Users\maorb\Classes\Classical_ML\YDATA-kaggle-assignment\venv\Lib\site-packages\httpcore\_sync\connection_pool.py", line 256, in handle_request
    raise exc from None
  File "C:\Users\maorb\Classes\Classical_ML\YDATA-kaggle-assignment\venv\Lib\site-packages\httpcore\_sync\connection_pool.py", line 236, in handle_request
    response = connection.handle_request(
               ^^^^^^^^^^^^^^^^^^^^^^^^^^
  File "C:\Users\maorb\Classes\Classical_ML\YDATA-kaggle-assignment\venv\Lib\site-packages\httpcore\_sync\connection.py", line 101, in handle_request
    raise exc
  File "C:\Users\maorb\Classes\Classical_ML\YDATA-kaggle-assignment\venv\Lib\site-packages\httpcore\_sync\connection.py", line 78, in handle_request
    stream = self._connect(request)
             ^^^^^^^^^^^^^^^^^^^^^^
  File "C:\Users\maorb\Classes\Classical_ML\YDATA-kaggle-assignment\venv\Lib\site-packages\httpcore\_sync\connection.py", line 124, in _connect
    stream = self._network_backend.connect_tcp(**kwargs)
             ^^^^^^^^^^^^^^^^^^^^^^^^^^^^^^^^^^^^^^^^^^^
  File "C:\Users\maorb\Classes\Classical_ML\YDATA-kaggle-assignment\venv\Lib\site-packages\httpcore\_backends\sync.py", line 207, in connect_tcp
    with map_exceptions(exc_map):
  File "C:\Users\maorb\AppData\Local\Programs\Python\Python312\Lib\contextlib.py", line 155, in __exit__
    self.gen.throw(value)
  File "C:\Users\maorb\Classes\Classical_ML\YDATA-kaggle-assignment\venv\Lib\site-packages\httpcore\_exceptions.py", line 14, in map_exceptions
    raise to_exc(exc) from exc
httpcore.ConnectError: [WinError 10061] No connection could be made because the target machine actively refused it

The above exception was the direct cause of the following exception:

Traceback (most recent call last):
  File "C:\Users\maorb\Classes\Classical_ML\YDATA-kaggle-assignment\wandb_test2.py", line 25, in <module>
    train_flow("data/processed", "data/processed")
  File "C:\Users\maorb\Classes\Classical_ML\YDATA-kaggle-assignment\venv\Lib\site-packages\prefect\flows.py", line 1392, in __call__
    return run_flow(
           ^^^^^^^^^
  File "C:\Users\maorb\Classes\Classical_ML\YDATA-kaggle-assignment\venv\Lib\site-packages\prefect\flow_engine.py", line 1511, in run_flow
    ret_val = run_flow_sync(**kwargs)
              ^^^^^^^^^^^^^^^^^^^^^^^
  File "C:\Users\maorb\Classes\Classical_ML\YDATA-kaggle-assignment\venv\Lib\site-packages\prefect\flow_engine.py", line 1351, in run_flow_sync
    with engine.start():
  File "C:\Users\maorb\AppData\Local\Programs\Python\Python312\Lib\contextlib.py", line 155, in __exit__
    self.gen.throw(value)
  File "C:\Users\maorb\Classes\Classical_ML\YDATA-kaggle-assignment\venv\Lib\site-packages\prefect\flow_engine.py", line 723, in start
    with self.initialize_run():
  File "C:\Users\maorb\AppData\Local\Programs\Python\Python312\Lib\contextlib.py", line 155, in __exit__
    self.gen.throw(value)
  File "C:\Users\maorb\Classes\Classical_ML\YDATA-kaggle-assignment\venv\Lib\site-packages\prefect\flow_engine.py", line 698, in initialize_run
    self.handle_crash(exc)
  File "C:\Users\maorb\Classes\Classical_ML\YDATA-kaggle-assignment\venv\Lib\site-packages\prefect\flow_engine.py", line 420, in handle_crash
    self.set_state(state, force=True)
  File "C:\Users\maorb\Classes\Classical_ML\YDATA-kaggle-assignment\venv\Lib\site-packages\prefect\flow_engine.py", line 306, in set_state
    state = propose_state_sync(
            ^^^^^^^^^^^^^^^^^^^
  File "C:\Users\maorb\Classes\Classical_ML\YDATA-kaggle-assignment\venv\Lib\site-packages\prefect\utilities\engine.py", line 476, in propose_state_sync
    response = set_state_and_handle_waits(set_state)
               ^^^^^^^^^^^^^^^^^^^^^^^^^^^^^^^^^^^^^
  File "C:\Users\maorb\Classes\Classical_ML\YDATA-kaggle-assignment\venv\Lib\site-packages\prefect\utilities\engine.py", line 458, in set_state_and_handle_waits
    response = set_state_func()
               ^^^^^^^^^^^^^^^^
  File "C:\Users\maorb\Classes\Classical_ML\YDATA-kaggle-assignment\venv\Lib\site-packages\prefect\client\orchestration\_flow_runs\client.py", line 332, in set_flow_run_state
    response = self.request(
               ^^^^^^^^^^^^^
  File "C:\Users\maorb\Classes\Classical_ML\YDATA-kaggle-assignment\venv\Lib\site-packages\prefect\client\orchestration\base.py", line 29, in request
    return self._client.request(method, path, params=params, **kwargs)
           ^^^^^^^^^^^^^^^^^^^^^^^^^^^^^^^^^^^^^^^^^^^^^^^^^^^^^^^^^^^
  File "C:\Users\maorb\Classes\Classical_ML\YDATA-kaggle-assignment\venv\Lib\site-packages\httpx\_client.py", line 825, in request
    return self.send(request, auth=auth, follow_redirects=follow_redirects)
           ^^^^^^^^^^^^^^^^^^^^^^^^^^^^^^^^^^^^^^^^^^^^^^^^^^^^^^^^^^^^^^^^
  File "C:\Users\maorb\Classes\Classical_ML\YDATA-kaggle-assignment\venv\Lib\site-packages\prefect\client\base.py", line 543, in send
    response = self._send_with_retry(
               ^^^^^^^^^^^^^^^^^^^^^^
  File "C:\Users\maorb\Classes\Classical_ML\YDATA-kaggle-assignment\venv\Lib\site-packages\prefect\client\base.py", line 467, in _send_with_retry
    response = send(request, *send_args, **send_kwargs)
               ^^^^^^^^^^^^^^^^^^^^^^^^^^^^^^^^^^^^^^^^
  File "C:\Users\maorb\Classes\Classical_ML\YDATA-kaggle-assignment\venv\Lib\site-packages\httpx\_client.py", line 914, in send
    response = self._send_handling_auth(
               ^^^^^^^^^^^^^^^^^^^^^^^^^
  File "C:\Users\maorb\Classes\Classical_ML\YDATA-kaggle-assignment\venv\Lib\site-packages\httpx\_client.py", line 942, in _send_handling_auth
    response = self._send_handling_redirects(
               ^^^^^^^^^^^^^^^^^^^^^^^^^^^^^^
  File "C:\Users\maorb\Classes\Classical_ML\YDATA-kaggle-assignment\venv\Lib\site-packages\httpx\_client.py", line 979, in _send_handling_redirects
    response = self._send_single_request(request)
               ^^^^^^^^^^^^^^^^^^^^^^^^^^^^^^^^^^
  File "C:\Users\maorb\Classes\Classical_ML\YDATA-kaggle-assignment\venv\Lib\site-packages\httpx\_client.py", line 1014, in _send_single_request
    response = transport.handle_request(request)
               ^^^^^^^^^^^^^^^^^^^^^^^^^^^^^^^^^
  File "C:\Users\maorb\Classes\Classical_ML\YDATA-kaggle-assignment\venv\Lib\site-packages\httpx\_transports\default.py", line 249, in handle_request
    with map_httpcore_exceptions():
  File "C:\Users\maorb\AppData\Local\Programs\Python\Python312\Lib\contextlib.py", line 155, in __exit__
    self.gen.throw(value)
  File "C:\Users\maorb\Classes\Classical_ML\YDATA-kaggle-assignment\venv\Lib\site-packages\httpx\_transports\default.py", line 118, in map_httpcore_exceptions
    raise mapped_exc(message) from exc
httpx.ConnectError: [WinError 10061] No connection could be made because the target machine actively refused it
--- Error logging to API ---
All connection attempts failed
