2025-01-26 16:18:39,482 INFO    MainThread:44752 [wandb_setup.py:_flush():68] Current SDK version is 0.19.4
2025-01-26 16:18:39,482 INFO    MainThread:44752 [wandb_setup.py:_flush():68] Configure stats pid to 44752
2025-01-26 16:18:39,482 INFO    MainThread:44752 [wandb_setup.py:_flush():68] Loading settings from C:\Users\maorb\.config\wandb\settings
2025-01-26 16:18:39,482 INFO    MainThread:44752 [wandb_setup.py:_flush():68] Loading settings from C:\Users\maorb\Classes\Classical_ML\YDATA-kaggle-assignment\wandb\settings
2025-01-26 16:18:39,482 INFO    MainThread:44752 [wandb_setup.py:_flush():68] Loading settings from environment variables
2025-01-26 16:18:39,483 INFO    MainThread:44752 [wandb_init.py:setup_run_log_directory():624] Logging user logs to C:\Users\maorb\Classes\Classical_ML\YDATA-kaggle-assignment\wandb\run-20250126_161839-at7qdzn3\logs\debug.log
2025-01-26 16:18:39,484 INFO    MainThread:44752 [wandb_init.py:setup_run_log_directory():625] Logging internal logs to C:\Users\maorb\Classes\Classical_ML\YDATA-kaggle-assignment\wandb\run-20250126_161839-at7qdzn3\logs\debug-internal.log
2025-01-26 16:18:39,484 INFO    MainThread:44752 [wandb_init.py:init():743] calling init triggers
2025-01-26 16:18:39,484 INFO    MainThread:44752 [wandb_init.py:init():748] wandb.init called with sweep_config: {}
config: {'model_name': 'catboost', 'val_size': 0.2, 'learning_rate': 0.03, 'iterations': 1000, 'class_weights': [1, 10]}
2025-01-26 16:18:39,484 INFO    MainThread:44752 [wandb_init.py:init():776] starting backend
2025-01-26 16:18:39,699 INFO    MainThread:44752 [wandb_init.py:init():780] sending inform_init request
2025-01-26 16:18:39,761 INFO    MainThread:44752 [wandb_init.py:init():795] backend started and connected
2025-01-26 16:18:39,763 INFO    MainThread:44752 [wandb_init.py:init():888] updated telemetry
2025-01-26 16:18:39,801 INFO    MainThread:44752 [wandb_init.py:init():915] communicating run to backend with 90.0 second timeout
2025-01-26 16:18:40,122 ERROR   MainThread:44752 [wandb_init.py:init():944] encountered error: failed to upsert bucket: returned error 403 Forbidden: {"errors":[{"message":"permission denied","path":["upsertBucket"],"extensions":{"code":"PERMISSION_ERROR"}}],"data":{"upsertBucket":null}}
2025-01-26 16:18:40,122 ERROR   MainThread:44752 [wandb_init.py:init():1454] error in wandb.init()
Traceback (most recent call last):
  File "C:\Users\maorb\Classes\Classical_ML\YDATA-kaggle-assignment\venv\Lib\site-packages\wandb\sdk\wandb_init.py", line 1444, in init
    return wi.init(run_settings, run_config)
           ^^^^^^^^^^^^^^^^^^^^^^^^^^^^^^^^^
  File "C:\Users\maorb\Classes\Classical_ML\YDATA-kaggle-assignment\venv\Lib\site-packages\wandb\sdk\wandb_init.py", line 950, in init
    raise error
wandb.errors.errors.CommError: failed to upsert bucket: returned error 403 Forbidden: {"errors":[{"message":"permission denied","path":["upsertBucket"],"extensions":{"code":"PERMISSION_ERROR"}}],"data":{"upsertBucket":null}}
2025-01-26 16:18:40,137 WARNING MsgRouterThr:44752 [router.py:message_loop():75] message_loop has been closed
